<?xml version='1.0' encoding='utf-8'?>
<robot name="robot">
    <link name="base_link">
        <inertial>
            <origin xyz="0.0038662210655893464 0.0 0.052675337982169175" rpy="0.0 0.0 0.0" />
            <mass value="17.13155401009962" />
            <inertia ixx="0.0584527227543141" iyy="0.06191909363698124" izz="0.10992638017861338" ixy="0.0" iyz="0.0" ixz="-0.002306589723332078" />
        </inertial>
        <visual name="base_link_visual">
            <origin xyz="0.0 0.0 0.0" rpy="0.0 0.0 0.0" />
            <geometry>
                <mesh filename="meshes/base_link.stl" scale="0.001 0.001 0.001" />
            </geometry>
        </visual>
        <collision name="base_link_collision">
            <origin xyz="0.0 0.0 0.0" rpy="0.0 0.0 0.0" />
            <geometry>
                <mesh filename="meshes/base_link.stl" scale="0.001 0.001 0.001" />
            </geometry>
        </collision>
    </link>
    <link name="right_wheel">
        <inertial>
            <origin xyz="5.7900231001220315e-18 0.0 0.012500000000000053" rpy="0.0 -0.0 0.0" />
            <mass value="1.5413438956674914" />
            <inertia ixx="0.0010436182626914897" iyy="0.0010436182626915452" izz="0.0019266798695843383" ixy="2.677325028344055e-19" iyz="1.734723475976807e-18" ixz="-1.7179502265207697e-18" />
        </inertial>
        <visual name="right_wheel_visual">
            <origin xyz="0.0 0.05 0.12500000000000003" rpy="1.5707963267948966 -0.0 0.0" />
            <geometry>
                <mesh filename="meshes/right_wheel.stl" scale="0.001 0.001 0.001" />
            </geometry>
        </visual>
        <collision name="right_wheel_collision">
            <origin xyz="0.0 0.05 0.12500000000000003" rpy="1.5707963267948966 -0.0 0.0" />
            <geometry>
                <mesh filename="meshes/right_wheel.stl" scale="0.001 0.001 0.001" />
            </geometry>
        </collision>
    </link>
    <link name="left_wheel">
        <inertial>
            <origin xyz="5.7900231001220315e-18 0.0 0.012500000000000018" rpy="0.0 -0.0 0.0" />
            <mass value="1.5413438956674914" />
            <inertia ixx="0.0010436182626914932" iyy="0.0010436182626915522" izz="0.0019266798695843383" ixy="2.677325028344058e-19" iyz="0.0" ixz="1.5394618912978329e-18" />
        </inertial>
        <visual name="left_wheel_visual">
            <origin xyz="0.0 0.05 -0.1" rpy="1.5707963267948966 -0.0 0.0" />
            <geometry>
                <mesh filename="meshes/left_wheel.stl" scale="0.001 0.001 0.001" />
            </geometry>
        </visual>
        <collision name="left_wheel_collision">
            <origin xyz="0.0 0.05 -0.1" rpy="1.5707963267948966 -0.0 0.0" />
            <geometry>
                <mesh filename="meshes/left_wheel.stl" scale="0.001 0.001 0.001" />
            </geometry>
        </collision>
    </link>
    <link name="lidar">
        <inertial>
            <origin xyz="0.0 0.0 0.009999999999999983" rpy="0.0 -0.0 0.0" />
            <mass value="0.6042068071016568" />
            <inertia ixx="0.0002051785615782651" iyy="0.0002051785615782755" izz="0.0003700766693497588" ixy="-8.924416761146858e-20" iyz="-4.908429218630772e-19" ixz="-4.336808689942018e-19" />
        </inertial>
        <visual name="lidar_visual">
            <origin xyz="-0.05 0.0 -0.1" rpy="0.0 -0.0 0.0" />
            <geometry>
                <mesh filename="meshes/lidar.stl" scale="0.001 0.001 0.001" />
            </geometry>
        </visual>
        <collision name="lidar_collision">
            <origin xyz="-0.05 0.0 -0.1" rpy="0.0 -0.0 0.0" />
            <geometry>
                <mesh filename="meshes/lidar.stl" scale="0.001 0.001 0.001" />
            </geometry>
        </collision>
    </link>
    <link name="camera">
        <inertial>
            <origin xyz="0.0 -1.167355140468276e-13 0.0030581760585232944" rpy="0.0 -0.0 0.0" />
            <mass value="0.02761393779133511" />
            <inertia ixx="1.4229288925050702e-06" iyy="1.422928887528528e-06" izz="2.5938721415465975e-06" ixy="1.394440118934782e-21" iyz="-1.7954610095097166e-18" ixz="0.0" />
        </inertial>
        <visual name="camera_visual">
            <origin xyz="-0.05 0.0 -0.1" rpy="-3.141592653589793 -1.5707963267948966 0" />
            <geometry>
                <mesh filename="meshes/camera.stl" scale="0.001 0.001 0.001" />
            </geometry>
        </visual>
        <collision name="camera_collision">
            <origin xyz="-0.05 0.0 -0.1" rpy="-3.141592653589793 -1.5707963267948966 0" />
            <geometry>
                <mesh filename="meshes/camera.stl" scale="0.001 0.001 0.001" />
            </geometry>
        </collision>
    </link>
    <joint name="base_link_Revolute-1" type="continuous">
        <origin xyz="0.0 0.1 0.05" rpy="-1.5707963267948966 -0.0 0.0" />
        <parent link="base_link" />
        <child link="left_wheel" />
        <axis xyz="0.0 0.0 1.0" />
    </joint>
    <joint name="base_link_Revolute-2" type="continuous">
        <origin xyz="0.0 -0.1 0.05" rpy="1.5707963267948966 -0.0 0.0" />
        <parent link="base_link" />
        <child link="right_wheel" />
        <axis xyz="0.0 0.0 -1.0" />
    </joint>
    <joint name="base_link_Rigid-3" type="fixed">
        <origin xyz="0.05 0.0 0.1" rpy="0.0 -0.0 0.0" />
        <parent link="base_link" />
        <child link="lidar" />
    </joint>
    <joint name="base_link_Rigid-4" type="fixed">
        <origin xyz="0.1 0.0 0.05" rpy="-3.141592653589793 -1.5707963267948966 0" />
        <parent link="base_link" />
        <child link="camera" />
    </joint>
</robot>